Workbook

Sheet Battle List
A1: Type | B1: Name | C1: NPC Source | D1: Quantity | E1: Group Name | F1: Initiative Mode | G1: HP Override | H1: Notes
A2: PC | B2: Rex | C2: Rex | D2: 1 | F2: Individual
A3: PC | B3: Prag | C3: Prag | D3: 1 | F3: Individual
A4: PC | B4: Roquist | C4: Roquist | D4: 1 | F4: Individual
A5: PC | B5: Giggles | C5: Giggles | D5: 1 | F5: Individual
A6: PC | B6: Shaddow | C6: Shaddow | D6: 1 | F6: Individual
A7: NPC | B7: Korrum | C7: Korrum | D7: 1 | F7: Individual
A8: NPC | B8: Veyrath | C8: Veyrath | D8: 1 | F8: Individual
A9: NPC | B9: Flame Wisp | D9: 3 | E9: Wisp Pack | F9: Grouped Attacks | G9: 10 | H9: Summoned by Veyrath (no stat tab; uses HP override)

Sheet Korrum
A1: CREATURE STAT BLOCK | J1: TRACKER HOOKS
J2: Attacks / Round | K2: 3
A3: Name | B3: Korrum | J3: (AC=B7, HP=B8, Init=B11, Atk1 to-hit=C28)
A4: Epithet | B4: Stone That Remembers
A5: Role | B5: Earth Elemental Commander
A6: Size / Type / Alignment | B6: Huge elemental, neutral
A7: AC | B7: 18
A8: Base HP | B8: 285
A9: Speed | B9: 30 ft., burrow 30 ft.
A10: Proficiency Bonus | B10: 4
A11: Initiative Mod | B11: =C16 -> -1
A13: ABILITY SCORES
B14: STR | C14: DEX | D14: CON | E14: INT | F14: WIS | G14: CHA
A15: Score | B15: 24 | C15: 8 | D15: 22 | E15: 8 | F15: 13 | G15: 11
A16: Modifier | B16: =INT((B15-10)/2) -> 7 | C16: =INT((C15-10)/2) -> -1 | D16: =INT((D15-10)/2) -> 6 | E16: =INT((E15-10)/2) -> -1 | F16: =INT((F15-10)/2) -> 1 | G16: =INT((G15-10)/2) -> 0
A17: Save Proficient | B17: Y | D17: Y | F17: Y
A18: Save Bonus | B18: =B16+IF(B17="Y",$B$10,0) -> 11 | C18: =C16+IF(C17="Y",$B$10,0) -> -1 | D18: =D16+IF(D17="Y",$B$10,0) -> 10 | E18: =E16+IF(E17="Y",$B$10,0) -> -1 | F18: =F16+IF(F17="Y",$B$10,0) -> 5 | G18: =G16+IF(G17="Y",$B$10,0) -> 0
A20: DEFENSES & SENSES
A21: Resistances | B21: bludgeoning, piercing, slashing from nonmagical attacks
A22: Immunities | B22: poison
A23: Condition Immunities | B23: exhaustion, paralyzed, petrified, poisoned, unconscious
A24: Senses | B24: darkvision 60 ft., tremorsense 60 ft., passive Perception 11
A26: ATTACKS
A27: Name | B27: Type | C27: To Hit | D27: Reach / Range | E27: Damage | F27: Save | G27: Effect
A28: Slam | B28: Melee Weapon | C28: 11 | D28: 10 ft. | E28: 3d8+7 bludgeoning | F28: DC 17 STR | G28: On hit, target pushed 10 ft. or knocked prone (DC 17 STR save).
A29: Boulder Hurl | B29: Ranged Weapon | C29: 11 | D29: 60/180 ft. | E29: 3d10+7 bludgeoning | F29: DC 17 STR | G29: If target is flying, DC 17 STR save or pushed 20 ft. and flying speed halved until start of its next turn.
A31: TRAITS
A32: Name | B32: Description
A33: Earth Glide | B33: Korrum can burrow through nonmagical, unworked earth and stone without disturbing it.
A34: Siege Monster | B34: Korrum deals double damage to objects and structures.
A35: Elemental Command: Stone Pressure | B35: While Korrum lives, each elemental flank deals +10 damage during flank resolution.
A36: Legendary Resistance (1/day) | B36: If Korrum fails a saving throw, it can choose to succeed instead.
A38: ACTIONS
A39: Name | B39: Recharge / Uses | C39: Save | D39: Description
A40: Multiattack | B40: — | C40: — | D40: Korrum makes three attacks, choosing between Slam and Boulder Hurl.
A41: Grasping Earth | B41: Recharge 5–6 | C41: DC 17 STR | D41: Choose a 20-ft. square of ground within 90 ft.; it becomes difficult terrain. Creatures in the area make a DC 17 STR save or be restrained. A restrained creature can repeat the save at the end of each of its turns, ending the effect on a success.
A43: BONUS ACTIONS
A44: Name | B44: Recharge / Uses | C44: Save | D44: Description
A45: Stone Spire | B45: — | C45: DC 16 DEX | D45: Raise a 10-ft.-wide, up to 30-ft.-tall stone pillar within 60 ft. (provides cover, blocks line of sight). A creature in the space makes a DC 16 DEX save or is lifted and knocked prone. Pillar: AC 17, HP 40.
A46: Stone Renewal | B46: 2x/day | C46: — | D46: If below ½ HP and touching earth or stone, regain 20 HP. Cannot use if, since the end of its last turn, it took thunder or force damage, was moved against its will, or a creature used an action to disrupt the ground with a successful DC 16 Arcana, Athletics, Nature, or mason's tools check.
...

Sheet Veyrath
A1: CREATURE STAT BLOCK | J1: TRACKER HOOKS
J2: Attacks / Round | K2: 3
A3: Name | B3: Veyrath | J3: (AC=B7, HP=B8, Init=B11, Atk1 to-hit=C28)
A4: Epithet | B4: the Crownflame
A5: Role | B5: Fire Elemental Commander
A6: Size / Type / Alignment | B6: Large elemental, neutral
A7: AC | B7: 17
A8: Base HP | B8: 240
A9: Speed | B9: 50 ft.
A10: Proficiency Bonus | B10: 4
A11: Initiative Mod | B11: =C16 -> 6
A13: ABILITY SCORES
B14: STR | C14: DEX | D14: CON | E14: INT | F14: WIS | G14: CHA
A15: Score | B15: 12 | C15: 22 | D15: 20 | E15: 10 | F15: 14 | G15: 16
A16: Modifier | B16: =INT((B15-10)/2) -> 1 | C16: =INT((C15-10)/2) -> 6 | D16: =INT((D15-10)/2) -> 5 | E16: =INT((E15-10)/2) -> 0 | F16: =INT((F15-10)/2) -> 2 | G16: =INT((G15-10)/2) -> 3
A17: Save Proficient | C17: Y | D17: Y | G17: Y
A18: Save Bonus | B18: =B16+IF(B17="Y",$B$10,0) -> 1 | C18: =C16+IF(C17="Y",$B$10,0) -> 10 | D18: =D16+IF(D17="Y",$B$10,0) -> 9 | E18: =E16+IF(E17="Y",$B$10,0) -> 0 | F18: =F16+IF(F17="Y",$B$10,0) -> 2 | G18: =G16+IF(G17="Y",$B$10,0) -> 7
A20: DEFENSES & SENSES
A21: Resistances | B21: bludgeoning, piercing, slashing from nonmagical attacks
A22: Immunities | B22: fire, poison
A23: Condition Immunities | B23: exhaustion, grappled, paralyzed, petrified, poisoned, prone, restrained, unconscious
A24: Senses | B24: darkvision 60 ft., passive Perception 12
A26: ATTACKS
A27: Name | B27: Type | C27: To Hit | D27: Reach / Range | E27: Damage | F27: Save | G27: Effect
A28: Burning Touch | B28: Melee Weapon | C28: 10 | D28: 5 ft. | E28: 2d8+6 fire | F28: — | G28: Target ignites: until a creature uses an action to extinguish, it takes 1d8 fire at the start of each of its turns. This ongoing damage does not stack.
A29: Ember Lance | B29: Ranged Spell | C29: 10 | D29: 120 ft. | E29: 3d8+6 fire | F29: — | G29: If the target is concentrating, the concentration save DC is at least 12.
A31: TRAITS
A32: Name | B32: Description
A33: Fire Form | B33: Veyrath can move through a space as narrow as 1 inch wide without squeezing. A creature that touches Veyrath or hits it with a melee attack while within 5 ft. takes 5 fire damage, no more than once per creature per round.
A34: Illumination | B34: Veyrath sheds bright light in a 30-ft. radius and dim light for another 30 ft.
A35: Elemental Command: Flame Pressure | B35: While Veyrath lives, each hobgoblin flank takes +10 fire attrition during flank resolution.
A36: Legendary Resistance (1/day) | B36: If Veyrath fails a saving throw, it can choose to succeed instead.
A38: ACTIONS
A39: Name | B39: Recharge / Uses | C39: Save | D39: Description
A40: Multiattack | B40: — | C40: — | D40: Veyrath makes three attacks, choosing between Burning Touch and Ember Lance.
A41: Thermal Updraft | B41: Recharge 4–6 | C41: DC 17 STR/DEX | D41: A 20-ft.-radius, 60-ft.-high cylinder of superheated air within 90 ft. Creatures make a DC 17 STR or DEX save. Failure: 4d6 fire damage and pushed 30 ft. (Veyrath's choice). Success: half damage, no push. Flying creatures that ended their last turn without moving 20+ ft. have disadvantage.
A42: Cinder Swarm | B42: Recharge 5–6 | C42: — | D42: Fills a 20-ft.-radius sphere within 120 ft. with ash and sparks until the end of its next turn; the area is heavily obscured. Creatures entering for the first time or starting their turn there take 3d6 fire damage. Ranged attacks through, into, or out of the area have disadvantage.
A44: BONUS ACTIONS
A45: Name | B45: Recharge / Uses | C45: Save | D45: Description
A46: Flame Renewal | B46: 2x/day | C46: — | D46: If below ½ HP and within 30 ft. of open flame, burning debris, or intense heat, regain 20 HP. Cannot use if, since the end of its last turn, it took cold or radiant damage, was doused or smothered, or a creature used an action to disrupt nearby flames with a successful DC 16 Arcana, Nature, Survival, or appropriate tool check.
...

Sheet Tracker
A1: ⚔ COMBAT TRACKER | P1: Round | Q1: Turn | R1: Source | S1: Target | T1: Event Type | U1: Amount | V1: Dmg Type | W1: Attack / Effect | X1: Notes
P2: 1 | Q2: 1 | R2: Giggles | S2: Flame Wisp 1 | T2: Damage | U2: 7 | V2: fire | W2: Firebolt | X2: Sample entry — delete to reset
A3: Round | B3: 1 | D3: Current Turn | E3: =IFERROR(INDEX($C$8:$C$19,MATCH($B$4,$A$8:$A$19,0)),"—") -> Prag | I3: Enemies Alive | J3: {=SUMPRODUCT(($D$8:$D$19="NPC")*($H$8:$H$19>0))} -> 3 | L3: Attacks in Pool | M3: {=SUMPRODUCT(($D$8:$D$19="NPC")*($H$8:$H$19>0)*$K$8:$K$19)} -> 9
A4: Turn # | B4: 3 | D4: Next Up | E4: =IFERROR(INDEX($C$8:$C$19,MATCH(IF($B$4>=MAX($A$8:$A$19),1,$B$4+1),$A$8:$A$19,0)),"—") -> Roquist | I4: Enemy HP Left | J4: =SUMIFS($H$8:$H$19,$D$8:$D$19,"NPC",$H$8:$H$19,">0") -> 548
B5: 2
A6: Tip: NPC initiative auto-rolls on F9. Type over any cell to override. Advance play by changing Turn # / Round above.
A7: Turn | B7: Init | C7: Name | D7: Type | E7: Group | F7: Active/Orig | G7: AC | H7: Cur HP | I7: Max HP | J7: Temp | K7: Atk Pool | L7: Conditions | M7: Status | N7: Notes
A8: =IF($B8="","",RANK($B8,$B$8:$B$19,0)+COUNTIF($B$8:$B8,$B8)-1) -> 2 | B8: 17 | C8: Rex | D8: PC | H8: =IF($I8="","",$I8-SUMIFS($U$2:$U$2000,$S$2:$S$2000,$C8,$T$2:$T$2000,"Damage")+SUMIFS($U$2:$U$2000,$S$2:$S$2000,$C8,$T$2:$T$2000,"Healing")) | M8: =IF($I8="","",IF($H8<=0,"Dead",IF($H8<=$I8/2,"Bloodied","Active")))
A9: =IF($B9="","",RANK($B9,$B$8:$B$19,0)+COUNTIF($B$8:$B9,$B9)-1) -> 3 | B9: 14 | C9: Prag | D9: PC | H9: =IF($I9="","",$I9-SUMIFS($U$2:$U$2000,$S$2:$S$2000,$C9,$T$2:$T$2000,"Damage")+SUMIFS($U$2:$U$2000,$S$2:$S$2000,$C9,$T$2:$T$2000,"Healing")) | M9: =IF($I9="","",IF($H9<=0,"Dead",IF($H9<=$I9/2,"Bloodied","Active")))
A10: =IF($B10="","",RANK($B10,$B$8:$B$19,0)+COUNTIF($B$8:$B10,$B10)-1) -> 4 | B10: 12 | C10: Roquist | D10: PC | H10: =IF($I10="","",$I10-SUMIFS($U$2:$U$2000,$S$2:$S$2000,$C10,$T$2:$T$2000,"Damage")+SUMIFS($U$2:$U$2000,$S$2:$S$2000,$C10,$T$2:$T$2000,"Healing")) | M10: =IF($I10="","",IF($H10<=0,"Dead",IF($H10<=$I10/2,"Bloodied","Active")))
A11: =IF($B11="","",RANK($B11,$B$8:$B$19,0)+COUNTIF($B$8:$B11,$B11)-1) -> 1 | B11: 19 | C11: Giggles | D11: PC | H11: =IF($I11="","",$I11-SUMIFS($U$2:$U$2000,$S$2:$S$2000,$C11,$T$2:$T$2000,"Damage")+SUMIFS($U$2:$U$2000,$S$2:$S$2000,$C11,$T$2:$T$2000,"Healing")) | M11: =IF($I11="","",IF($H11<=0,"Dead",IF($H11<=$I11/2,"Bloodied","Active")))
A12: =IF($B12="","",RANK($B12,$B$8:$B$19,0)+COUNTIF($B$8:$B12,$B12)-1) -> 6 | B12: 9 | C12: Shaddow | D12: PC | H12: =IF($I12="","",$I12-SUMIFS($U$2:$U$2000,$S$2:$S$2000,$C12,$T$2:$T$2000,"Damage")+SUMIFS($U$2:$U$2000,$S$2:$S$2000,$C12,$T$2:$T$2000,"Healing")) | M12: =IF($I12="","",IF($H12<=0,"Dead",IF($H12<=$I12/2,"Bloodied","Active")))
A13: =IF($B13="","",RANK($B13,$B$8:$B$19,0)+COUNTIF($B$8:$B13,$B13)-1) -> 7 | B13: 8 | C13: Korrum | D13: NPC | F13: — | G13: =Korrum!B7 -> 18 | H13: =IF($I13="","",$I13-SUMIFS($U$2:$U$2000,$S$2:$S$2000,$C13,$T$2:$T$2000,"Damage")+SUMIFS($U$2:$U$2000,$S$2:$S$2000,$C13,$T$2:$T$2000,"Healing")) -> 285 | I13: =Korrum!B8 -> 285 | K13: =IF($H13>0,Korrum!K2,0) -> 3 | M13: =IF($I13="","",IF($H13<=0,"Dead",IF($H13<=$I13/2,"Bloodied","Active"))) -> Active
A14: =IF($B14="","",RANK($B14,$B$8:$B$19,0)+COUNTIF($B$8:$B14,$B14)-1) -> 8 | B14: 7 | C14: Veyrath | D14: NPC | F14: — | G14: =Veyrath!B7 -> 17 | H14: =IF($I14="","",$I14-SUMIFS($U$2:$U$2000,$S$2:$S$2000,$C14,$T$2:$T$2000,"Damage")+SUMIFS($U$2:$U$2000,$S$2:$S$2000,$C14,$T$2:$T$2000,"Healing")) -> 240 | I14: =Veyrath!B8 -> 240 | K14: =IF($H14>0,Veyrath!K2,0) -> 3 | M14: =IF($I14="","",IF($H14<=0,"Dead",IF($H14<=$I14/2,"Bloodied","Active"))) -> Active
A15: =IF($B15="","",RANK($B15,$B$8:$B$19,0)+COUNTIF($B$8:$B15,$B15)-1) -> 5 | B15: 10 | C15: Wisp Pack | D15: NPC | E15: Wisp Pack | F15: =COUNTIFS($B$25:$B$60,$E15,$D$25:$D$60,">0")&" / "&COUNTIFS($B$25:$B$60,$E15) -> 3 / 3 | G15: — | H15: =SUMIFS($D$25:$D$60,$B$25:$B$60,$E15) -> 23 | I15: =SUMIFS($C$25:$C$60,$B$25:$B$60,$E15) -> 30 | K15: =SUMIFS($G$25:$G$60,$B$25:$B$60,$E15,$F$25:$F$60,"Y",$D$25:$D$60,">0") -> 3 | M15: =IF($I15="","",IF($H15<=0,"Dead",IF($H15<=$I15/2,"Bloodied","Active"))) -> Active
A23: GROUP / MEMBER ENGINE (individual HP retained; group row aggregates these)
A24: Member | B24: Group | C24: Max HP | D24: Cur HP | E24: Status | F24: Can Attack? | G24: Atk/Member | H24: Conditions | I24: GROUP DAMAGE ASSISTANT | L24: INITIATIVE ROLLER — press F9, then type results into the Init column
A25: Flame Wisp 1 | B25: Wisp Pack | C25: ='Battle List'!$G$9 -> 10 | D25: =IF($C25="","",$C25-SUMIFS($U$2:$U$2000,$S$2:$S$2000,$A25,$T$2:$T$2000,"Damage")+SUMIFS($U$2:$U$2000,$S$2:$S$2000,$A25,$T$2:$T$2000,"Healing")) -> 3 | E25: =IF($D25="","",IF($D25<=0,"Dead",IF($D25<=$C25/2,"Bloodied","Active"))) -> Bloodied | F25: Y | G25: 1 | I25: Group | J25: Wisp Pack | L25: NPC | M25: Roll (d20+mod)
A26: Flame Wisp 2 | B26: Wisp Pack | C26: ='Battle List'!$G$9 -> 10 | D26: =IF($C26="","",$C26-SUMIFS($U$2:$U$2000,$S$2:$S$2000,$A26,$T$2:$T$2000,"Damage")+SUMIFS($U$2:$U$2000,$S$2:$S$2000,$A26,$T$2:$T$2000,"Healing")) -> 10 | E26: =IF($D26="","",IF($D26<=0,"Dead",IF($D26<=$C26/2,"Bloodied","Active"))) -> Active | F26: Y | G26: 1 | I26: Incoming Damage | J26: 16 | L26: Korrum | M26: =RANDBETWEEN(1,20)+Korrum!B11 -> 15
A27: Flame Wisp 3 | B27: Wisp Pack | C27: ='Battle List'!$G$9 -> 10 | D27: =IF($C27="","",$C27-SUMIFS($U$2:$U$2000,$S$2:$S$2000,$A27,$T$2:$T$2000,"Damage")+SUMIFS($U$2:$U$2000,$S$2:$S$2000,$A27,$T$2:$T$2000,"Healing")) -> 10 | E27: =IF($D27="","",IF($D27<=0,"Dead",IF($D27<=$C27/2,"Bloodied","Active"))) -> Active | F27: Y | G27: 1 | I27: Active Members | J27: =COUNTIFS($B$25:$B$60,$J$25,$D$25:$D$60,">0") -> 3 | L27: Veyrath | M27: =RANDBETWEEN(1,20)+Veyrath!B11 -> 18
I28: Even Split / Member | J28: =IF($J$27=0,0,ROUNDUP($J$26/$J$27,0)) -> 6 | L28: Wisp Pack | M28: =RANDBETWEEN(1,20)+2 -> 14
I29: Casualties (mob est.) | J29: =IFERROR(INT($J$26/AVERAGEIFS($C$25:$C$60,$B$25:$B$60,$J$25)),0) -> 1
A30: BATCH ATTACK ROLLER — press F9 to re-roll | I30: Focused: log one Damage event to a single member. Front-loaded: apply to the lowest-HP member first, carry overflow to next.
A31: # Attacks | B31: To Hit | C31: Target AC | D31: Avg Dmg/Hit
A32: 8 | B32: 5 | C32: 17 | D32: 9
A34: Roll | B34: =RANDBETWEEN(1,20) -> 8 | C34: =RANDBETWEEN(1,20) -> 18 | D34: =RANDBETWEEN(1,20) -> 14 | E34: =RANDBETWEEN(1,20) -> 16 | F34: =RANDBETWEEN(1,20) -> 5 | G34: =RANDBETWEEN(1,20) -> 13 | H34: =RANDBETWEEN(1,20) -> 4 | I34: =RANDBETWEEN(1,20) -> 3 | ... K34: =RANDBETWEEN(1,20) -> 13
A35: Roll+Hit | B35: =B34+$B$32 -> 13 | C35: =C34+$B$32 -> 23 | D35: =D34+$B$32 -> 19 | E35: =E34+$B$32 -> 21 | F35: =F34+$B$32 -> 10 | G35: =G34+$B$32 -> 18 | H35: =H34+$B$32 -> 9 | I35: =I34+$B$32 -> 8 | ... K35: =K34+$B$32 -> 18
A36: Result | B36: =IF((COLUMN()-COLUMN($B$36)+1)>$A$32,"",IF(OR(B34=20,B35>=$C$32),"HIT","miss")) -> miss | C36: =IF((COLUMN()-COLUMN($B$36)+1)>$A$32,"",IF(OR(C34=20,C35>=$C$32),"HIT","miss")) -> HIT | D36: =IF((COLUMN()-COLUMN($B$36)+1)>$A$32,"",IF(OR(D34=20,D35>=$C$32),"HIT","miss")) -> HIT | E36: =IF((COLUMN()-COLUMN($B$36)+1)>$A$32,"",IF(OR(E34=20,E35>=$C$32),"HIT","miss")) -> HIT | F36: =IF((COLUMN()-COLUMN($B$36)+1)>$A$32,"",IF(OR(F34=20,F35>=$C$32),"HIT","miss")) -> miss | G36: =IF((COLUMN()-COLUMN($B$36)+1)>$A$32,"",IF(OR(G34=20,G35>=$C$32),"HIT","miss")) -> HIT | H36: =IF((COLUMN()-COLUMN($B$36)+1)>$A$32,"",IF(OR(H34=20,H35>=$C$32),"HIT","miss")) -> miss | I36: =IF((COLUMN()-COLUMN($B$36)+1)>$A$32,"",IF(OR(I34=20,I35>=$C$32),"HIT","miss")) -> miss | ... K36: =IF((COLUMN()-COLUMN($B$36)+1)>$A$32,"",IF(OR(K34=20,K35>=$C$32),"HIT","miss"))
A38: Hits | B38: =COUNTIF(B36:K36,"HIT") -> 4 | C38: Est Damage | D38: =B38*$D$32 -> 36
A41: MOB RESOLUTION — expected hits for large formations
A42: # Attackers | B42: To Hit | C42: Target AC | F42: Min Roll | G42: Attackers/Hit
A43: 40 | B43: 5 | C43: 20 | F43: 1 | G43: 1
A44: Req. d20 Roll | B44: =MIN(20,MAX(1,$C$43-$B$43)) -> 15 | F44: 6 | G44: 2
A45: Attackers / Hit | B45: =VLOOKUP($B$44,$F$43:$G$49,2,TRUE) -> 4 | F45: 13 | G45: 3
A46: Estimated Hits | B46: =INT($A$43/$B$45) -> 10 | F46: 15 | G46: 4
A47: Override Hits (opt) | F47: 17 | G47: 5
A48: Avg Dmg / Hit | B48: 7 | F48: 19 | G48: 10
A49: Total Damage | B49: =IF($B$47="",$B$46,$B$47)*$B$48 -> 70 | F49: 20 | G49: 20
A51: HOW TO USE
A52: • Initiative: NPC rows auto-roll on F9; type players' rolls into the Init column. Turn order re-sorts automatically.
...
